# 코딩도장 38

## 예외 처리 사용하기

예외(exception)란 코드를 실행하는 중에 발생한 에러를 뜻한다.

### try except로 사용하기

예외 처리를 하려면 try에 실행할 코드를 넣고 except에 예외가 발생했을 때 처리하는 코드를 넣는다.

```python
try:
	실행할코드
except:
	예외가 발생했을 때 처리하는 코드
```

```python
try:
	x = int(input('나눌 숫자를 입력하세요:'))
	y = 10 / x
	print(y)
expect:
	print('예외 발생')
```

예외가 발생하면 해당 줄에서 코드 실행을 중당하고 바로 except로 가서 코드를 실행한다. try의 y = 10 / x를 비로하여 print(y)도 실행되지 않는다. try의 코드에서 에러가 발생했을 때만 except의 코드가 실행된다.





### 특정 예외만 처리하기

```python
try:
	실행할 코드
except 예외이름:
	예외가 발생했을 때 처리하는 코드
```

```python
y = [10, 20, 30]
 
try:
    index, x = map(int, input('인덱스와 나눌 숫자를 입력하세요: ').split())
    print(y[index] / x)
except ZeroDivisionError:    # 숫자를 0으로 나눠서 에러가 발생했을 때 실행됨
    print('숫자를 0으로 나눌 수 없습니다.')
except IndexError:           # 범위를 벗어난 인덱스에 접근하여 에러가 발생했을 때 실행됨
    print('잘못된 인덱스입니다.')
```





### 예외의 에러 메시지 받아오기

except에서 as 뒤에 변수를 지정하면 발생한 예외의 에러 메시지를 받아올 수 있다

```python
try:
	실행할 코드
except 예외 as 변수:
	예외가 발생했을 때 처리하는 코드
```

except 에 as e를 넣는다. 보통 예외(exception)의 e를 따서 변수 이름을 e로 짓는다.

```python
y = [10, 20, 30]
 
try:
    index, x = map(int, input('인덱스와 나눌 숫자를 입력하세요: ').split())
    print(y[index] / x)
except ZeroDivisionError as e:                    # as 뒤에 변수를 지정하면 에러를 받아옴
    print('숫자를 0으로 나눌 수 없습니다.', e)    # e에 저장된 에러 메시지 출력
except IndexError as e:
    print('잘못된 인덱스입니다.', e)
```

```python
숫자를 0으로 나눌 수 없습니다. division by zero
잘못된 인덱스입니다. list index out of range
```

예외가 여러 개 발생하더라도 먼저 발생한 예외의 처리 코드만 실행된다. 또는 예외 중에서 높은 계층의 예외부터 처리된다. (기반 클래스 > 파생 클래스 순)

모든 예외에 에러 메시지를 출력하고 싶다면 except에 Exception을 지정하고 as 뒤에 변수를 넣으면 된다.

```python
except Exception as e:
	print('예외가 발생했다', e)
```

예외 처리는 에러가 발생하더라도 스크립트의 실행을 중단시키지 않고 계속 실행하고자 할 때 사용한다.



#### 예외 계층

예외도 클래스 상속으로 구현되며 계층으로 이루어져 있다.







## else와 finally 사용하기

else는 except 바로 다음에 와야 하며 except를 생략할 수 있다.

```python
try:
    실행할 코드
except:
    예외가 발생했을 때 처리하는 코드
else:
    예외가 발생하지 않았을 때 실행할 코드
```





### 예외와는 상관없이 항상 코드 실행하기

예외 발생 여부와 상관없이 finally를 사용하면 항상 코드를 실행한다.

```python
try:
    실행할 코드
except:
    예외가 발생했을 때 처리하는 코드
else:
    예외가 발생하지 않았을 때 실행할 코드
finally:
    예외 발생 여부와 상관없이 항상 실행할 코드
```





### try 안에서 만든 변수는 try 바깥에서도 사용할 수 있나?

try는 함수가 아니므로 스택 프레임을 만들지 않기에 try 바깥에서도 사용할 수 있다.







## 예외 발생시키기

예외를 발생시킬 때는 raise에 예외를 지정하고 에러 메시지를 넣는다(에러 메시지는 생략 가능)

- raise 예외('에러메시지')

```python
try:
	x = int(input('3의 배수를 입력하세요: '))
    if x % 3 != 0:
        raise Exception('3의 배수가 아니다')
    print(x)
except Exception as e:
    print('예외가 발생했다.', e)
```

Exception에 넣은 에러 메시지는 except Exception as e: 의 e에 들어간다. raise로 예외를 발생시키면 raise 아래에 있는 코드는 실행되지 않고 바로 except로 넘어간다. try 의 print(x)는 실행되지 않는다.





### raise의 처리 과정

expect 안에서 raise를 사용하면 현재 예외를 다시 발생시킨다.(re-raise)

- raise

```python
def three_multiple():
    try:
        x = int(input('3의 배수를 입력하세요: '))
        if x % 3 != 0:                                 # x가 3의 배수가 아니면
            raise Exception('3의 배수가 아닙니다.')    # 예외를 발생시킴
        print(x)
    except Exception as e:                             # 함수 안에서 예외를 처리함
        print('three_multiple 함수에서 예외가 발생했습니다.', e)
        raise    # raise로 현재 예외를 다시 발생시켜서 상위 코드 블록으로 넘김
 
try:
    three_multiple()
except Exception as e:                                 # 하위 코드 블록에서 예외가 발생해도 실행됨
    print('스크립트 파일에서 예외가 발생했습니다.', e)
```

```
3의 배수를 입력하세요: 5 (입력)
three_multiple 함수에서 예외가 발생했습니다. 3의 배수가 아닙니다.
스크립트 파일에서 예외가 발생했습니다. 3의 배수가 아닙니다.
```

raise를 사용하면 같은 예외를 계속 처리해줄 수 있다. raise만 사용하면 같은 예외를 상위 코드 블록으로 넘기지만 raise에 다른 예외를 지정하고 에러 메시지를 넣을 수도 있다.

- raise 예외('에러메시지')

```python
        if x % 3 != 0:
            raise Exception('3의 배수가 아닙니다.')
        print(x)
    except Exception as e:
        print('three_multiple 함수에서 예외가 발생했습니다.', e)
        raise RuntimeError('three_multiple 함수에서 예외가 발생했습니다.')
```





#### assert로 예외 발생시키기

예외를 발생시키는 방법 중에는 assert를 사용하는 방법도 있다

assert는 지정된 조건이 것일 때 AssertionError 예외를 발생시키면 조건식이 참이면 그냥 넘어간다.

- assert 조건식
- assert 조건식, 에러메시지

```python
x = int(input('3의 배수를 입력하세요: '))
assert x % 3 == 0, '3의 배수가 아닙니다.'    # 3의 배수가 아니면 예외 발생, 3의 배수이면 그냥 넘어감
print(x)
```

assert는 디버깅 모드에서만 실행된다. 파이썬에서는 기본적으로 디버깅 모드에며 assert가 실행되지 않게 하려면 python에 -O 옵션을 붙여서 실행한다.







## 에러 만들기

프로그래머가 직접 만든 예외를 사용자 정의 예외라고 한다.

Exception을 상속받아서 새로운 클래슬르 만들면 된다. \__init\_\_메서드에서 기반 클래스의 \_\_init__ 메서드를 호출하면서 에러 메시지를 넣어주면 된다.

```python
class 예외이름(Exception):
	def __init__(self):
		super().__init__('에러메시지')
```

```python
class NotThreeMultipleError(Exception):
	def __init__(self):
		super().__init__('3의 배수가 아니다')
	

def three_multiple():
	try:
		x = int(input('3의 배수를 입력하세요'))
		if x % 3 != 0:
			raise NotThreeMultipleError
		print(x)
	except Exception as e:
		print('예외가 발생했습니다', e)
		
three_multiple()
```

Exception만 상속받고 pass를 넣어서 아무것도 구현하지 않아도 된다. 이때는 에러를 발생시킬 때 에러 메시지를 넣어주면 된다.

```python
raise NotThreeMultipleError('3의 배수가 아닙니다.')    # 예외를 발생시킬 때 에러 메시지를 넣음
```

